<?xml version="1.0" ?>
<!-- =================================================================================== -->
<!-- |    This document was autogenerated by xacro from arm_5dof.xacro                 | -->
<!-- |    EDITING THIS FILE BY HAND IS NOT RECOMMENDED                                 | -->
<!-- =================================================================================== -->
<robot name="schunk_arm_5dof" xmlns:xacro="http://ros.org/wiki/xacro">
  <material name="black">
    <color rgba="0 0 0 1"/>
  </material>
  <material name="gray">
    <color rgba="0.15 0.15 0.15 1"/>
  </material>
  <!-- Joints -->
  <joint name="Fixed_A" type="fixed">
    <origin rpy="0 0 0" xyz="0 0 0.0725"/>
    <parent link="PAM112_BaseConector"/>
    <child link="P90_1_LowerCube"/>
  </joint>
  <joint name="Joint0" type="revolute">
    <origin rpy="0 0 0" xyz="0 0 0.09"/>
    <parent link="P90_1_LowerCube"/>
    <child link="P90_1_UpperCube"/>
    <limit effort="2" lower="-3.0543" upper="3.0543" velocity="0.8"/>
    <axis xyz="0 0 1"/>
  </joint>
  <joint name="Fixed_B" type="fixed">
    <origin rpy="0 0 0" xyz="0 0 0.0675"/>
    <parent link="P90_1_UpperCube"/>
    <child link="PAM102"/>
  </joint>
  <joint name="Fixed_C" type="fixed">
    <origin rpy="0 0 0" xyz="0 0 0.0675"/>
    <parent link="PAM102"/>
    <child link="P90_2_LowerCube"/>
  </joint>
  <joint name="Joint1" type="revolute">
    <origin rpy="0 0 0" xyz="0 0.09 0"/>
    <parent link="P90_2_LowerCube"/>
    <child link="P90_2_UpperCube"/>
    <limit effort="2" lower="-2.0071" upper="2.0071" velocity="0.8"/>
    <axis xyz="0 1 0"/>
  </joint>
  <joint name="Fixed_D" type="fixed">
    <origin rpy="0 0 0" xyz="0 -0.00025 0.106"/>
    <parent link="P90_2_UpperCube"/>
    <child link="PAM121"/>
  </joint>
  <joint name="Fixed_E" type="fixed">
    <origin rpy="0 0 0" xyz="0 -0.09025 0.016"/>
    <parent link="PAM121"/>
    <child link="P90_3_LowerCube"/>
  </joint>
  <joint name="Joint2" type="revolute">
    <origin rpy="0 0 0" xyz="0 0 0.09 "/>
    <parent link="P90_3_LowerCube"/>
    <child link="P90_3_UpperCube"/>
    <limit effort="2" lower="-2.8099" upper="2.8099" velocity="0.8"/>
    <axis xyz="0 0 1"/>
  </joint>
  <joint name="Fixed_F" type="fixed">
    <origin rpy="0 0 0" xyz="0 0 0.0675"/>
    <parent link="P90_3_UpperCube"/>
    <child link="PAM110"/>
  </joint>
  <joint name="Fixed_G" type="fixed">
    <origin rpy="0 0 0" xyz="0 0 0.0575"/>
    <parent link="PAM110"/>
    <child link="P70_1_LowerCube"/>
  </joint>
  <joint name="Joint3" type="revolute">
    <origin rpy="0 0 0" xyz="0 -0.07 0 "/>
    <parent link="P70_1_LowerCube"/>
    <child link="P70_1_UpperCube"/>
    <limit effort="2" lower="-0.78539816339744828" upper="2.007" velocity="0.8"/>
    <axis xyz="0 -1 0"/>
  </joint>
  <joint name="Fixed_H" type="fixed">
    <origin rpy="0 0 0" xyz="0 -0.00025 0.084"/>
    <parent link="P70_1_UpperCube"/>
    <child link="PAM120"/>
  </joint>
  <joint name="Fixed_I" type="fixed">
    <origin rpy="0 0 0" xyz="0 0.07025 0.014"/>
    <parent link="PAM120"/>
    <child link="P70_2_LowerCube"/>
  </joint>
  <joint name="Joint4" type="revolute">
    <origin rpy="0 0 0" xyz="0  0 0.07"/>
    <parent link="P70_2_LowerCube"/>
    <child link="P70_2_UpperCube"/>
    <limit effort="2" lower="-2.8099" upper="2.8099" velocity="0.8"/>
    <axis xyz="0 0 1"/>
  </joint>
  <joint name="Fixed_J" type="fixed">
    <origin rpy="0 0 0" xyz="0 0 0.0525"/>
    <parent link="P70_2_UpperCube"/>
    <child link="PAM100"/>
  </joint>
  <joint name="Fixed_Base" type="fixed">
    <origin rpy="0 0 3.14159265358979323846" xyz="0 0  0.6075"/>
    <parent link="ScitosBase"/>
    <child link="PAM112_BaseConector"/>
  </joint>
  <!-- Links -->
  <link name="ScitosBase">
    <visual>
      <origin rpy="0 0 0" xyz="0 0 0.29"/>
      <geometry>
        <cylinder length="0.58" radius="0.18"/>
      </geometry>
      <material name="scitosblue">
        <color rgba=".0 .0 .5 1"/>
      </material>
    </visual>
    <collision>
      <origin rpy="0 0 0" xyz="0 0 0.29"/>
      <geometry>
        <cylinder length="0.58" radius="0.18"/>
      </geometry>
    </collision>
  </link>
  <link name="PAM112_BaseConector">
    <visual>
      <origin rpy="0 0 0" xyz="0 0 0"/>
      <geometry>
        <cylinder length="0.055" radius="0.045"/>
      </geometry>
      <material name="black"/>
    </visual>
    <collision>
      <geometry>
        <cylinder length="0.055" radius="0.045"/>
      </geometry>
    </collision>
  </link>
  <link name="P90_1_LowerCube">
    <visual>
      <origin rpy="0 0 0" xyz="0 0 0"/>
      <geometry>
        <box size="0.09 0.09 0.09"/>
      </geometry>
      <material name="gray"/>
    </visual>
    <collision>
      <geometry>
        <box size="0.09 0.09 0.09"/>
      </geometry>
    </collision>
  </link>
  <link name="P90_1_UpperCube">
    <visual>
      <origin rpy="0 0 0" xyz="0 0 0"/>
      <geometry>
        <box size="0.09 0.09 0.09"/>
      </geometry>
      <material name="gray"/>
    </visual>
    <collision>
      <geometry>
        <box size="0.09 0.09 0.09"/>
      </geometry>
    </collision>
  </link>
  <link name="PAM102">
    <visual>
      <origin rpy="0 0 0" xyz="0 0 0"/>
      <geometry>
        <cylinder length="0.045" radius="0.045"/>
      </geometry>
      <material name="black"/>
    </visual>
    <collision>
      <geometry>
        <cylinder length="0.045" radius="0.045"/>
      </geometry>
    </collision>
  </link>
  <link name="P90_2_LowerCube">
    <visual>
      <origin rpy="0 0 0" xyz="0 0 0"/>
      <geometry>
        <box size="0.09 0.09 0.09"/>
      </geometry>
      <material name="gray"/>
    </visual>
    <collision>
      <geometry>
        <box size="0.09 0.09 0.09"/>
      </geometry>
    </collision>
  </link>
  <link name="P90_2_UpperCube">
    <visual>
      <origin rpy="0 0 0" xyz="0 0 0"/>
      <geometry>
        <box size="0.09 0.09 0.09"/>
      </geometry>
      <material name="gray"/>
    </visual>
    <collision>
      <geometry>
        <box size="0.09 0.09 0.09"/>
      </geometry>
    </collision>
  </link>
  <link name="PAM121">
    <visual>
      <origin rpy="0 0 0" xyz="0 0 0"/>
      <geometry>
        <box size="0.048 0.0905 0.122 "/>
      </geometry>
      <material name="black"/>
    </visual>
    <collision>
      <geometry>
        <box size="0.048 0.0905 0.122 "/>
      </geometry>
    </collision>
  </link>
  <link name="P90_3_LowerCube">
    <visual>
      <origin rpy="0 0 0" xyz="0 0 0"/>
      <geometry>
        <box size="0.09 0.09 0.09"/>
      </geometry>
      <material name="gray"/>
    </visual>
    <collision>
      <geometry>
        <box size="0.09 0.09 0.09"/>
      </geometry>
    </collision>
  </link>
  <link name="P90_3_UpperCube">
    <visual>
      <origin rpy="0 0 0" xyz="0 0 0"/>
      <geometry>
        <box size="0.09 0.09 0.09"/>
      </geometry>
      <material name="gray"/>
    </visual>
    <collision>
      <geometry>
        <box size="0.09 0.09 0.09"/>
      </geometry>
    </collision>
  </link>
  <link name="PAM110">
    <visual>
      <origin rpy="0 0 0" xyz="0 0 0"/>
      <geometry>
        <cylinder length="0.045" radius="0.035"/>
      </geometry>
      <material name="black"/>
    </visual>
    <collision>
      <geometry>
        <cylinder length="0.045" radius="0.035"/>
      </geometry>
    </collision>
  </link>
  <link name="P70_1_LowerCube">
    <visual>
      <origin rpy="0 0 0" xyz="0 0 0"/>
      <geometry>
        <box size="0.07 0.07 0.07 "/>
      </geometry>
      <material name="gray"/>
    </visual>
    <collision>
      <geometry>
        <box size="0.07 0.07 0.07 "/>
      </geometry>
    </collision>
  </link>
  <link name="P70_1_UpperCube">
    <visual>
      <origin rpy="0 0 0" xyz="0 0 0"/>
      <geometry>
        <box size="0.07 0.07 0.07 "/>
      </geometry>
      <material name="gray"/>
    </visual>
    <collision>
      <geometry>
        <box size="0.07 0.07 0.07 "/>
      </geometry>
    </collision>
  </link>
  <link name="PAM120">
    <visual>
      <origin rpy="0 0 0" xyz="0 0 0"/>
      <geometry>
        <box size="0.007 0.0705 0.098 "/>
      </geometry>
      <material name="black"/>
    </visual>
    <collision>
      <geometry>
        <box size="0.007 0.0705 0.098 "/>
      </geometry>
    </collision>
  </link>
  <link name="P70_2_LowerCube">
    <visual>
      <origin rpy="0 0 0" xyz="0 0 0"/>
      <geometry>
        <box size="0.07 0.07 0.07 "/>
      </geometry>
      <material name="gray"/>
    </visual>
    <collision>
      <geometry>
        <box size="0.07 0.07 0.07 "/>
      </geometry>
    </collision>
  </link>
  <link name="P70_2_UpperCube">
    <visual>
      <origin rpy="0 0 0" xyz="0 0 0"/>
      <geometry>
        <box size="0.07 0.07 0.07 "/>
      </geometry>
      <material name="gray"/>
    </visual>
    <collision>
      <geometry>
        <box size="0.07 0.07 0.07 "/>
      </geometry>
    </collision>
  </link>
  <link name="PAM100">
    <visual>
      <origin rpy="0 0 0" xyz="0 0 0"/>
      <geometry>
        <cylinder length="0.035" radius="0.025"/>
      </geometry>
      <material name="black"/>
    </visual>
    <collision>
      <geometry>
        <cylinder length="0.035" radius="0.025"/>
      </geometry>
    </collision>
  </link>
</robot>

