<?xml version="1.0" ?>
<!-- =================================================================================== -->
<!-- |    This document was autogenerated by xacro from xacro/arm_hand.xacro           | -->
<!-- |    EDITING THIS FILE BY HAND IS NOT RECOMMENDED                                 | -->
<!-- =================================================================================== -->
<robot name="schunk_arm_hand" xmlns:controller="http://playerstage.sourceforge.net/gazebo/xmlschema/#controller" xmlns:interface="http://playerstage.sourceforge.net/gazebo/xmlschema/#interface" xmlns:sensor="http://playerstage.sourceforge.net/gazebo/xmlschema/#sensor" xmlns:xacro="http://ros.org/wiki/xacro">
  <!-- Arm -->
  <material name="black">
    <color rgba="0 0 0 1"/>
  </material>
  <material name="gray">
    <color rgba="0.15 0.15 0.15 1"/>
  </material>
  <joint name="Fixed_A" type="fixed">
    <origin rpy="0 0 0" xyz="0 0 0.0725"/>
    <parent link="PAM112_BaseConector"/>
    <child link="P90_1_LowerCube"/>
  </joint>
  <joint name="Joint0" type="revolute">
    <origin rpy="0 0 0" xyz="0 0 0.09"/>
    <parent link="P90_1_LowerCube"/>
    <child link="P90_1_UpperCube"/>
    <limit effort="2" lower="-3.0543" upper="3.0543" velocity="0.8"/>
    <axis xyz="0 0 1"/>
  </joint>
  <joint name="Fixed_B" type="fixed">
    <origin rpy="0 0 0" xyz="0 0 0.0675"/>
    <parent link="P90_1_UpperCube"/>
    <child link="PAM102"/>
  </joint>
  <joint name="Fixed_C" type="fixed">
    <origin rpy="0 0 0" xyz="0 0 0.0675"/>
    <parent link="PAM102"/>
    <child link="P90_2_LowerCube"/>
  </joint>
  <joint name="Joint1" type="revolute">
    <origin rpy="0 0 0" xyz="0 0.09 0"/>
    <parent link="P90_2_LowerCube"/>
    <child link="P90_2_UpperCube"/>
    <limit effort="2" lower="-2.0071" upper="2.0071" velocity="0.8"/>
    <axis xyz="0 1 0"/>
  </joint>
  <joint name="Fixed_D" type="fixed">
    <origin rpy="0 0 0" xyz="0 -0.00025 0.106"/>
    <parent link="P90_2_UpperCube"/>
    <child link="PAM121"/>
  </joint>
  <joint name="Fixed_E" type="fixed">
    <origin rpy="0 0 0" xyz="0 -0.09025 0.016"/>
    <parent link="PAM121"/>
    <child link="P90_3_LowerCube"/>
  </joint>
  <joint name="Joint2" type="revolute">
    <origin rpy="0 0 0" xyz="0 0 0.09 "/>
    <parent link="P90_3_LowerCube"/>
    <child link="P90_3_UpperCube"/>
    <limit effort="2" lower="-2.8099" upper="2.8099" velocity="0.8"/>
    <axis xyz="0 0 1"/>
  </joint>
  <joint name="Fixed_F" type="fixed">
    <origin rpy="0 0 0" xyz="0 0 0.0675"/>
    <parent link="P90_3_UpperCube"/>
    <child link="PAM110"/>
  </joint>
  <joint name="Fixed_G" type="fixed">
    <origin rpy="0 0 0" xyz="0 0 0.0575"/>
    <parent link="PAM110"/>
    <child link="P70_1_LowerCube"/>
  </joint>
  <joint name="Joint3" type="revolute">
    <origin rpy="0 0 0" xyz="0 -0.07 0 "/>
    <parent link="P70_1_LowerCube"/>
    <child link="P70_1_UpperCube"/>
    <limit effort="2" lower="-0.78539816339744828" upper="2.007" velocity="0.8"/>
    <axis xyz="0 -1 0"/>
  </joint>
  <joint name="Fixed_H" type="fixed">
    <origin rpy="0 0 0" xyz="0 -0.00025 0.084"/>
    <parent link="P70_1_UpperCube"/>
    <child link="PAM120"/>
  </joint>
  <joint name="Fixed_I" type="fixed">
    <origin rpy="0 0 0" xyz="0 0.07025 0.014"/>
    <parent link="PAM120"/>
    <child link="P70_2_LowerCube"/>
  </joint>
  <joint name="Joint4" type="revolute">
    <origin rpy="0 0 0" xyz="0  0 0.07"/>
    <parent link="P70_2_LowerCube"/>
    <child link="P70_2_UpperCube"/>
    <limit effort="2" lower="-2.8099" upper="2.8099" velocity="0.8"/>
    <axis xyz="0 0 1"/>
  </joint>
  <joint name="Fixed_J" type="fixed">
    <origin rpy="0 0 0" xyz="0 0 0.0525"/>
    <parent link="P70_2_UpperCube"/>
    <child link="PAM100"/>
  </joint>
  <joint name="Fixed_Base" type="fixed">
    <origin rpy="0 0 3.14159265358979323846" xyz="0 0  0.6075"/>
    <parent link="ScitosBase"/>
    <child link="PAM112_BaseConector"/>
  </joint>
  <link name="ScitosBase">
    <visual>
      <origin rpy="0 0 0" xyz="0 0 0.29"/>
      <geometry>
        <cylinder length="0.58" radius="0.18"/>
      </geometry>
      <material name="scitosblue">
        <color rgba=".0 .0 .5 1"/>
      </material>
    </visual>
    <collision>
      <origin rpy="0 0 0" xyz="0 0 0.29"/>
      <geometry>
        <cylinder length="0.58" radius="0.18"/>
      </geometry>
    </collision>
  </link>
  <link name="PAM112_BaseConector">
    <visual>
      <origin rpy="0 0 0" xyz="0 0 0"/>
      <geometry>
        <cylinder length="0.055" radius="0.045"/>
      </geometry>
      <material name="black"/>
    </visual>
    <collision>
      <geometry>
        <cylinder length="0.055" radius="0.045"/>
      </geometry>
    </collision>
  </link>
  <link name="P90_1_LowerCube">
    <visual>
      <origin rpy="0 0 0" xyz="0 0 0"/>
      <geometry>
        <box size="0.09 0.09 0.09"/>
      </geometry>
      <material name="gray"/>
    </visual>
    <collision>
      <geometry>
        <box size="0.09 0.09 0.09"/>
      </geometry>
    </collision>
  </link>
  <link name="P90_1_UpperCube">
    <visual>
      <origin rpy="0 0 0" xyz="0 0 0"/>
      <geometry>
        <box size="0.09 0.09 0.09"/>
      </geometry>
      <material name="gray"/>
    </visual>
    <collision>
      <geometry>
        <box size="0.09 0.09 0.09"/>
      </geometry>
    </collision>
  </link>
  <link name="PAM102">
    <visual>
      <origin rpy="0 0 0" xyz="0 0 0"/>
      <geometry>
        <cylinder length="0.045" radius="0.045"/>
      </geometry>
      <material name="black"/>
    </visual>
    <collision>
      <geometry>
        <cylinder length="0.045" radius="0.045"/>
      </geometry>
    </collision>
  </link>
  <link name="P90_2_LowerCube">
    <visual>
      <origin rpy="0 0 0" xyz="0 0 0"/>
      <geometry>
        <box size="0.09 0.09 0.09"/>
      </geometry>
      <material name="gray"/>
    </visual>
    <collision>
      <geometry>
        <box size="0.09 0.09 0.09"/>
      </geometry>
    </collision>
  </link>
  <link name="P90_2_UpperCube">
    <visual>
      <origin rpy="0 0 0" xyz="0 0 0"/>
      <geometry>
        <box size="0.09 0.09 0.09"/>
      </geometry>
      <material name="gray"/>
    </visual>
    <collision>
      <geometry>
        <box size="0.09 0.09 0.09"/>
      </geometry>
    </collision>
  </link>
  <link name="PAM121">
    <visual>
      <origin rpy="0 0 0" xyz="0 0 0"/>
      <geometry>
        <box size="0.048 0.0905 0.122 "/>
      </geometry>
      <material name="black"/>
    </visual>
    <collision>
      <geometry>
        <box size="0.048 0.0905 0.122 "/>
      </geometry>
    </collision>
  </link>
  <link name="P90_3_LowerCube">
    <visual>
      <origin rpy="0 0 0" xyz="0 0 0"/>
      <geometry>
        <box size="0.09 0.09 0.09"/>
      </geometry>
      <material name="gray"/>
    </visual>
    <collision>
      <geometry>
        <box size="0.09 0.09 0.09"/>
      </geometry>
    </collision>
  </link>
  <link name="P90_3_UpperCube">
    <visual>
      <origin rpy="0 0 0" xyz="0 0 0"/>
      <geometry>
        <box size="0.09 0.09 0.09"/>
      </geometry>
      <material name="gray"/>
    </visual>
    <collision>
      <geometry>
        <box size="0.09 0.09 0.09"/>
      </geometry>
    </collision>
  </link>
  <link name="PAM110">
    <visual>
      <origin rpy="0 0 0" xyz="0 0 0"/>
      <geometry>
        <cylinder length="0.045" radius="0.035"/>
      </geometry>
      <material name="black"/>
    </visual>
    <collision>
      <geometry>
        <cylinder length="0.045" radius="0.035"/>
      </geometry>
    </collision>
  </link>
  <link name="P70_1_LowerCube">
    <visual>
      <origin rpy="0 0 0" xyz="0 0 0"/>
      <geometry>
        <box size="0.07 0.07 0.07 "/>
      </geometry>
      <material name="gray"/>
    </visual>
    <collision>
      <geometry>
        <box size="0.07 0.07 0.07 "/>
      </geometry>
    </collision>
  </link>
  <link name="P70_1_UpperCube">
    <visual>
      <origin rpy="0 0 0" xyz="0 0 0"/>
      <geometry>
        <box size="0.07 0.07 0.07 "/>
      </geometry>
      <material name="gray"/>
    </visual>
    <collision>
      <geometry>
        <box size="0.07 0.07 0.07 "/>
      </geometry>
    </collision>
  </link>
  <link name="PAM120">
    <visual>
      <origin rpy="0 0 0" xyz="0 0 0"/>
      <geometry>
        <box size="0.007 0.0705 0.098 "/>
      </geometry>
      <material name="black"/>
    </visual>
    <collision>
      <geometry>
        <box size="0.007 0.0705 0.098 "/>
      </geometry>
    </collision>
  </link>
  <link name="P70_2_LowerCube">
    <visual>
      <origin rpy="0 0 0" xyz="0 0 0"/>
      <geometry>
        <box size="0.07 0.07 0.07 "/>
      </geometry>
      <material name="gray"/>
    </visual>
    <collision>
      <geometry>
        <box size="0.07 0.07 0.07 "/>
      </geometry>
    </collision>
  </link>
  <link name="P70_2_UpperCube">
    <visual>
      <origin rpy="0 0 0" xyz="0 0 0"/>
      <geometry>
        <box size="0.07 0.07 0.07 "/>
      </geometry>
      <material name="gray"/>
    </visual>
    <collision>
      <geometry>
        <box size="0.07 0.07 0.07 "/>
      </geometry>
    </collision>
  </link>
  <link name="PAM100">
    <visual>
      <origin rpy="0 0 0" xyz="0 0 0"/>
      <geometry>
        <cylinder length="0.035" radius="0.025"/>
      </geometry>
      <material name="black"/>
    </visual>
    <collision>
      <geometry>
        <cylinder length="0.035" radius="0.025"/>
      </geometry>
    </collision>
  </link>
  <!-- Hand -->
  <material name="Blue">
    <color rgba="0.0 0.0 0.8 1.0"/>
  </material>
  <material name="Green">
    <color rgba="0.0 0.8 0.0 1.0"/>
  </material>
  <material name="Grey">
    <color rgba="0.2 0.2 0.2 1.0"/>
  </material>
  <material name="LightGrey">
    <color rgba="0.6 0.6 0.6 1.0"/>
  </material>
  <material name="Red">
    <color rgba="0.8 0.0 0.0 1.0"/>
  </material>
  <material name="White">
    <color rgba="1.0 1.0 1.0 1.0"/>
  </material>
  <gazebo>
    <controller:gazebo_ros_controller_manager name="gazebo_ros_controller_manager" plugin="libgazebo_ros_controller_manager.so">
      <alwaysOn>true</alwaysOn>
      <updateRate>1000.0</updateRate>
    </controller:gazebo_ros_controller_manager>
  </gazebo>
  <link name="forearm_motor">
    <inertial>
      <origin xyz="0 0 0"/>
      <mass value="3.0"/>
      <inertia ixx="1.0" ixy="0.0" ixz="0.0" iyy="0.0" iyz="0.0" izz="0.0"/>
    </inertial>
    <visual>
      <origin rpy="0 0 -1.57079632679" xyz="0 0 0"/>
      <geometry name="shadow_forearm_geom">
        <mesh filename="package://sr_hand/model/meshes/forearm.mesh"/>
      </geometry>
      <material name="Grey"/>
    </visual>
    <collision>
      <origin rpy="0 0 0" xyz="0 0 0.09"/>
      <geometry name="shadow_forearm_collision">
        <cylinder length="0.180" radius="0.06"/>
      </geometry>
    </collision>
  </link>
  <gazebo reference="forearm_motor">
    <material>Gazebo/Grey</material>
    <selfCollide>true</selfCollide>
  </gazebo>
  <link name="wrist">
    <inertial>
      <!--<origin xyz="0 0.010 0.213" rpy="0 0 0" />-->
      <origin rpy="0 0 0" xyz="0 0.010 0.213"/>
      <mass value="0.3"/>
      <inertia ixx="1.0" ixy="0.0" ixz="0.0" iyy="0.0" iyz="0.0" izz="0.0"/>
    </inertial>
    <visual>
      <origin rpy="1.57079632679 0 0" xyz="0 0 0"/>
      <geometry name="wrist_visual">
        <mesh filename="package://sr_hand/model/meshes/wrist.mesh" scale="0.001 0.001 0.001"/>
      </geometry>
      <material name="LightGrey"/>
    </visual>
    <collision>
      <origin rpy="0 0 0" xyz="0 0 0"/>
      <geometry name="wrist_collision_geom">
        <box size="0.02 0.02 0.02"/>
      </geometry>
    </collision>
  </link>
  <gazebo reference="wrist">
    <material>PR2/Grey2</material>
    <selfCollide>true</selfCollide>
  </gazebo>
  <joint name="WRJ2" type="revolute">
    <parent link="forearm_motor"/>
    <child link="wrist"/>
    <!--<origin xyz="0 -0.010 0.213" rpy="0 0 0" />-->
    <origin rpy="0 0 0" xyz="0 0.010 0.213"/>
    <axis xyz="0 1 0"/>
    <limit effort="10" lower="-0.52359877559829882" upper="0.17453292519943295" velocity="1.0"/>
    <dynamics damping="50.5"/>
  </joint>
  <transmission name="wrist_transmission" type="pr2_mechanism_model/SimpleTransmission">
    <actuator name="WRJ2"/>
    <joint name="WRJ2"/>
    <mechanicalReduction>1</mechanicalReduction>
    <motorTorqueConstant>1</motorTorqueConstant>
    <pulsesPerRevolution>90000</pulsesPerRevolution>
  </transmission>
  <link name="palm">
    <inertial>
      <origin rpy="0 0 0" xyz="0 0.010 0.247"/>
      <mass value="0.3"/>
      <inertia ixx="1.0" ixy="0.0" ixz="0.0" iyy="0.0" iyz="0.0" izz="0.0"/>
    </inertial>
    <visual>
      <origin rpy="0 -1.57079632679 0" xyz="0 0 0"/>
      <geometry name="palm_visual">
        <mesh filename="package://sr_hand/model/meshes/palm.mesh" scale="0.001 0.001 0.001"/>
      </geometry>
      <material name="Grey"/>
    </visual>
    <collision>
      <origin rpy="0 0 0" xyz="0.005 0 0.035"/>
      <geometry name="palm_collision_geom">
        <box size="0.05 0.02 0.07"/>
      </geometry>
    </collision>
  </link>
  <gazebo reference="palm">
    <material>Gazebo/Grey</material>
  </gazebo>
  <joint name="WRJ1" type="revolute">
    <parent link="wrist"/>
    <child link="palm"/>
    <origin rpy="0 0 0" xyz="0 0 0.034"/>
    <axis xyz="1 0 0"/>
    <limit effort="10" lower="-0.78539816339744828" upper="0.6108652381980153" velocity="1.0"/>
    <dynamics damping="50.5"/>
  </joint>
  <transmission name="palm_transmission" type="pr2_mechanism_model/SimpleTransmission">
    <actuator name="WRJ1"/>
    <joint name="WRJ1"/>
    <mechanicalReduction>1</mechanicalReduction>
    <motorTorqueConstant>1</motorTorqueConstant>
    <pulsesPerRevolution>90000</pulsesPerRevolution>
  </transmission>
  <link name="ffknuckle">
    <inertial>
      <!--<origin xyz="0.011 0 0.099" rpy="0 0 0" />-->
      <origin rpy="0 0 0" xyz="0.033 0 0.095"/>
      <mass value="0.008"/>
      <inertia ixx="1.0" ixy="0.0" ixz="0.0" iyy="0.0" iyz="0.0" izz="0.0"/>
    </inertial>
    <visual>
      <origin rpy="3.14159265359 -1.57079632679 -1.57079632679" xyz="0 0 0.0005"/>
      <geometry name="knuckle_visual">
        <mesh filename="package://sr_hand/model/meshes/knuckle.mesh" scale="0.001 0.001 0.001"/>
      </geometry>
      <material name="LightGrey"/>
    </visual>
    <collision>
      <origin rpy="0 0 0" xyz="0 0 0"/>
      <geometry name="knuckle_collision_geom">
        <box size="0.005 0.005 0.005"/>
      </geometry>
    </collision>
  </link>
  <gazebo reference="ffknuckle">
    <material>PR2/Grey2</material>
  </gazebo>
  <joint name="FFJ4" type="revolute">
    <parent link="palm"/>
    <child link="ffknuckle"/>
    <!--<origin xyz="0.033 0 0.095" rpy="0 0 0" />-->
    <origin rpy="0 0 0" xyz="0.033 0 0.095"/>
    <axis xyz="0 -1 0"/>
    <limit effort="10" lower="-0.43633231299858238" upper="0.43633231299858238" velocity="1.0"/>
    <dynamics damping="50.5"/>
  </joint>
  <transmission name="ffknuckle_transmission" type="pr2_mechanism_model/SimpleTransmission">
    <actuator name="FFJ4"/>
    <joint name="FFJ4"/>
    <mechanicalReduction>1</mechanicalReduction>
    <motorTorqueConstant>1</motorTorqueConstant>
    <pulsesPerRevolution>90000</pulsesPerRevolution>
  </transmission>
  <link name="ffproximal">
    <inertial>
      <mass value="0.014"/>
      <origin xyz="0 0 0"/>
      <inertia ixx="1.0" ixy="0.0" ixz="0.0" iyy="0.0" iyz="0.0" izz="0.0"/>
    </inertial>
    <visual>
      <origin rpy="0 -1.57079632679 1.57079632679" xyz="0 0 0"/>
      <geometry name="proximal_visual">
        <mesh filename="package://sr_hand/model/meshes/F3.mesh" scale="0.001 0.001 0.001"/>
      </geometry>
      <material name="Grey"/>
    </visual>
    <collision>
      <origin rpy="0 0 0 " xyz="0 0 0.0225"/>
      <geometry name="proximal_collision_geom">
        <box size="0.005 0.005 0.04"/>
      </geometry>
    </collision>
  </link>
  <gazebo reference="ffproximal">
    <material>Gazebo/Grey</material>
  </gazebo>
  <joint name="FFJ3" type="revolute">
    <parent link="ffknuckle"/>
    <child link="ffproximal"/>
    <origin rpy="0 0 0" xyz="0 0 0"/>
    <axis xyz="1 0 0"/>
    <limit effort="10" lower="0" upper="1.57079632679" velocity="1.0"/>
    <dynamics damping="50.5"/>
  </joint>
  <transmission name="ffproximal_transmission" type="pr2_mechanism_model/SimpleTransmission">
    <actuator name="FFJ3"/>
    <joint name="FFJ3"/>
    <mechanicalReduction>1</mechanicalReduction>
    <motorTorqueConstant>1</motorTorqueConstant>
    <pulsesPerRevolution>90000</pulsesPerRevolution>
  </transmission>
  <link name="ffmiddle">
    <inertial>
      <origin rpy="0 0 0" xyz="0 0 0.045"/>
      <mass value="0.012"/>
      <inertia ixx="1.0" ixy="0.0" ixz="0.0" iyy="0.0" iyz="0.0" izz="0.0"/>
    </inertial>
    <visual>
      <origin rpy="0 -1.57079632679 0" xyz="0 0 0"/>
      <geometry name="middle_visual">
        <mesh filename="package://sr_hand/model/meshes/F2.mesh" scale="0.001 0.001 0.001"/>
      </geometry>
      <material name="Grey"/>
    </visual>
    <collision>
      <origin rpy="0 0 0" xyz="0 0 0.0125"/>
      <geometry name="middle_collision_geom">
        <box size="0.005 0.005 0.010"/>
      </geometry>
    </collision>
  </link>
  <gazebo reference="ffmiddle">
    <material>Gazebo/Grey</material>
  </gazebo>
  <joint name="FFJ2" type="revolute">
    <parent link="ffproximal"/>
    <child link="ffmiddle"/>
    <origin rpy="0 0 0" xyz="0 0 0.045"/>
    <axis xyz="1 0 0"/>
    <limit effort="10" lower="0" upper="1.57079632679" velocity="1.0"/>
    <dynamics damping="50.5"/>
  </joint>
  <transmission name="ffmiddle_transmission" type="pr2_mechanism_model/SimpleTransmission">
    <actuator name="FFJ2"/>
    <joint name="FFJ2"/>
    <mechanicalReduction>1</mechanicalReduction>
    <motorTorqueConstant>1</motorTorqueConstant>
    <pulsesPerRevolution>90000</pulsesPerRevolution>
  </transmission>
  <link name="ffdistal">
    <inertial>
      <mass value="0.010"/>
      <origin xyz="0 0 0.025"/>
      <inertia ixx="1.0" ixy="0.0" ixz="0.0" iyy="0.0" iyz="0.0" izz="0.0"/>
    </inertial>
    <visual>
      <origin rpy="0 -1.57079632679 0" xyz="0 0 0"/>
      <geometry name="distal_visual">
        <mesh filename="package://sr_hand/model/meshes/F1.mesh" scale="0.001 0.001 0.001"/>
      </geometry>
      <material name="Grey"/>
    </visual>
    <collision>
      <origin rpy="0 0 0" xyz="0 0 0.02"/>
      <geometry name="distal_collision_geom">
        <box size="0.015 0.015 0.020"/>
      </geometry>
    </collision>
  </link>
  <gazebo reference="ffdistal">
    <material>Gazebo/Grey</material>
  </gazebo>
  <joint name="FFJ1" type="revolute">
    <parent link="ffmiddle"/>
    <child link="ffdistal"/>
    <origin rpy="0 0 0" xyz="0 0 0.025"/>
    <axis xyz="1 0 0"/>
    <limit effort="10" lower="0" upper="1.57079632679" velocity="1.0"/>
    <dynamics damping="50.5"/>
  </joint>
  <transmission name="ffdistal_transmission" type="pr2_mechanism_model/SimpleTransmission">
    <actuator name="FFJ1"/>
    <joint name="FFJ1"/>
    <mechanicalReduction>1</mechanicalReduction>
    <motorTorqueConstant>1</motorTorqueConstant>
    <pulsesPerRevolution>90000</pulsesPerRevolution>
  </transmission>
  <link name="mfknuckle">
    <inertial>
      <!--<origin xyz="0.011 0 0.099" rpy="0 0 0" />-->
      <origin rpy="0 0 0" xyz="0.011 0 0.099"/>
      <mass value="0.008"/>
      <inertia ixx="1.0" ixy="0.0" ixz="0.0" iyy="0.0" iyz="0.0" izz="0.0"/>
    </inertial>
    <visual>
      <origin rpy="3.14159265359 -1.57079632679 -1.57079632679" xyz="0 0 0.0005"/>
      <geometry name="knuckle_visual">
        <mesh filename="package://sr_hand/model/meshes/knuckle.mesh" scale="0.001 0.001 0.001"/>
      </geometry>
      <material name="LightGrey"/>
    </visual>
    <collision>
      <origin rpy="0 0 0" xyz="0 0 0"/>
      <geometry name="knuckle_collision_geom">
        <box size="0.005 0.005 0.005"/>
      </geometry>
    </collision>
  </link>
  <gazebo reference="mfknuckle">
    <material>PR2/Grey2</material>
  </gazebo>
  <joint name="MFJ4" type="revolute">
    <parent link="palm"/>
    <child link="mfknuckle"/>
    <!--<origin xyz="0.033 0 0.095" rpy="0 0 0" />-->
    <origin rpy="0 0 0" xyz="0.011 0 0.099"/>
    <axis xyz="0 -1 0"/>
    <limit effort="10" lower="-0.43633231299858238" upper="0.43633231299858238" velocity="1.0"/>
    <dynamics damping="50.5"/>
  </joint>
  <transmission name="mfknuckle_transmission" type="pr2_mechanism_model/SimpleTransmission">
    <actuator name="MFJ4"/>
    <joint name="MFJ4"/>
    <mechanicalReduction>1</mechanicalReduction>
    <motorTorqueConstant>1</motorTorqueConstant>
    <pulsesPerRevolution>90000</pulsesPerRevolution>
  </transmission>
  <link name="mfproximal">
    <inertial>
      <mass value="0.014"/>
      <origin xyz="0 0 0"/>
      <inertia ixx="1.0" ixy="0.0" ixz="0.0" iyy="0.0" iyz="0.0" izz="0.0"/>
    </inertial>
    <visual>
      <origin rpy="0 -1.57079632679 1.57079632679" xyz="0 0 0"/>
      <geometry name="proximal_visual">
        <mesh filename="package://sr_hand/model/meshes/F3.mesh" scale="0.001 0.001 0.001"/>
      </geometry>
      <material name="Grey"/>
    </visual>
    <collision>
      <origin rpy="0 0 0 " xyz="0 0 0.0225"/>
      <geometry name="proximal_collision_geom">
        <box size="0.005 0.005 0.04"/>
      </geometry>
    </collision>
  </link>
  <gazebo reference="mfproximal">
    <material>Gazebo/Grey</material>
  </gazebo>
  <joint name="MFJ3" type="revolute">
    <parent link="mfknuckle"/>
    <child link="mfproximal"/>
    <origin rpy="0 0 0" xyz="0 0 0"/>
    <axis xyz="1 0 0"/>
    <limit effort="10" lower="0" upper="1.57079632679" velocity="1.0"/>
    <dynamics damping="50.5"/>
  </joint>
  <transmission name="mfproximal_transmission" type="pr2_mechanism_model/SimpleTransmission">
    <actuator name="MFJ3"/>
    <joint name="MFJ3"/>
    <mechanicalReduction>1</mechanicalReduction>
    <motorTorqueConstant>1</motorTorqueConstant>
    <pulsesPerRevolution>90000</pulsesPerRevolution>
  </transmission>
  <link name="mfmiddle">
    <inertial>
      <origin rpy="0 0 0" xyz="0 0 0.045"/>
      <mass value="0.012"/>
      <inertia ixx="1.0" ixy="0.0" ixz="0.0" iyy="0.0" iyz="0.0" izz="0.0"/>
    </inertial>
    <visual>
      <origin rpy="0 -1.57079632679 0" xyz="0 0 0"/>
      <geometry name="middle_visual">
        <mesh filename="package://sr_hand/model/meshes/F2.mesh" scale="0.001 0.001 0.001"/>
      </geometry>
      <material name="Grey"/>
    </visual>
    <collision>
      <origin rpy="0 0 0" xyz="0 0 0.0125"/>
      <geometry name="middle_collision_geom">
        <box size="0.005 0.005 0.010"/>
      </geometry>
    </collision>
  </link>
  <gazebo reference="mfmiddle">
    <material>Gazebo/Grey</material>
  </gazebo>
  <joint name="MFJ2" type="revolute">
    <parent link="mfproximal"/>
    <child link="mfmiddle"/>
    <origin rpy="0 0 0" xyz="0 0 0.045"/>
    <axis xyz="1 0 0"/>
    <limit effort="10" lower="0" upper="1.57079632679" velocity="1.0"/>
    <dynamics damping="50.5"/>
  </joint>
  <transmission name="mfmiddle_transmission" type="pr2_mechanism_model/SimpleTransmission">
    <actuator name="MFJ2"/>
    <joint name="MFJ2"/>
    <mechanicalReduction>1</mechanicalReduction>
    <motorTorqueConstant>1</motorTorqueConstant>
    <pulsesPerRevolution>90000</pulsesPerRevolution>
  </transmission>
  <link name="mfdistal">
    <inertial>
      <mass value="0.010"/>
      <origin xyz="0 0 0.025"/>
      <inertia ixx="1.0" ixy="0.0" ixz="0.0" iyy="0.0" iyz="0.0" izz="0.0"/>
    </inertial>
    <visual>
      <origin rpy="0 -1.57079632679 0" xyz="0 0 0"/>
      <geometry name="distal_visual">
        <mesh filename="package://sr_hand/model/meshes/F1.mesh" scale="0.001 0.001 0.001"/>
      </geometry>
      <material name="Grey"/>
    </visual>
    <collision>
      <origin rpy="0 0 0" xyz="0 0 0.02"/>
      <geometry name="distal_collision_geom">
        <box size="0.015 0.015 0.020"/>
      </geometry>
    </collision>
  </link>
  <gazebo reference="mfdistal">
    <material>Gazebo/Grey</material>
  </gazebo>
  <joint name="MFJ1" type="revolute">
    <parent link="mfmiddle"/>
    <child link="mfdistal"/>
    <origin rpy="0 0 0" xyz="0 0 0.025"/>
    <axis xyz="1 0 0"/>
    <limit effort="10" lower="0" upper="1.57079632679" velocity="1.0"/>
    <dynamics damping="50.5"/>
  </joint>
  <transmission name="mfdistal_transmission" type="pr2_mechanism_model/SimpleTransmission">
    <actuator name="MFJ1"/>
    <joint name="MFJ1"/>
    <mechanicalReduction>1</mechanicalReduction>
    <motorTorqueConstant>1</motorTorqueConstant>
    <pulsesPerRevolution>90000</pulsesPerRevolution>
  </transmission>
  <link name="rfknuckle">
    <inertial>
      <!--<origin xyz="0.011 0 0.099" rpy="0 0 0" />-->
      <origin rpy="0 0 0" xyz="-0.011 0 0.095"/>
      <mass value="0.008"/>
      <inertia ixx="1.0" ixy="0.0" ixz="0.0" iyy="0.0" iyz="0.0" izz="0.0"/>
    </inertial>
    <visual>
      <origin rpy="3.14159265359 -1.57079632679 -1.57079632679" xyz="0 0 0.0005"/>
      <geometry name="knuckle_visual">
        <mesh filename="package://sr_hand/model/meshes/knuckle.mesh" scale="0.001 0.001 0.001"/>
      </geometry>
      <material name="LightGrey"/>
    </visual>
    <collision>
      <origin rpy="0 0 0" xyz="0 0 0"/>
      <geometry name="knuckle_collision_geom">
        <box size="0.005 0.005 0.005"/>
      </geometry>
    </collision>
  </link>
  <gazebo reference="rfknuckle">
    <material>PR2/Grey2</material>
  </gazebo>
  <joint name="RFJ4" type="revolute">
    <parent link="palm"/>
    <child link="rfknuckle"/>
    <!--<origin xyz="0.033 0 0.095" rpy="0 0 0" />-->
    <origin rpy="0 0 0" xyz="-0.011 0 0.095"/>
    <axis xyz="0 1 0"/>
    <limit effort="10" lower="-0.43633231299858238" upper="0.43633231299858238" velocity="1.0"/>
    <dynamics damping="50.5"/>
  </joint>
  <transmission name="rfknuckle_transmission" type="pr2_mechanism_model/SimpleTransmission">
    <actuator name="RFJ4"/>
    <joint name="RFJ4"/>
    <mechanicalReduction>1</mechanicalReduction>
    <motorTorqueConstant>1</motorTorqueConstant>
    <pulsesPerRevolution>90000</pulsesPerRevolution>
  </transmission>
  <link name="rfproximal">
    <inertial>
      <mass value="0.014"/>
      <origin xyz="0 0 0"/>
      <inertia ixx="1.0" ixy="0.0" ixz="0.0" iyy="0.0" iyz="0.0" izz="0.0"/>
    </inertial>
    <visual>
      <origin rpy="0 -1.57079632679 1.57079632679" xyz="0 0 0"/>
      <geometry name="proximal_visual">
        <mesh filename="package://sr_hand/model/meshes/F3.mesh" scale="0.001 0.001 0.001"/>
      </geometry>
      <material name="Grey"/>
    </visual>
    <collision>
      <origin rpy="0 0 0 " xyz="0 0 0.0225"/>
      <geometry name="proximal_collision_geom">
        <box size="0.005 0.005 0.04"/>
      </geometry>
    </collision>
  </link>
  <gazebo reference="rfproximal">
    <material>Gazebo/Grey</material>
  </gazebo>
  <joint name="RFJ3" type="revolute">
    <parent link="rfknuckle"/>
    <child link="rfproximal"/>
    <origin rpy="0 0 0" xyz="0 0 0"/>
    <axis xyz="1 0 0"/>
    <limit effort="10" lower="0" upper="1.57079632679" velocity="1.0"/>
    <dynamics damping="50.5"/>
  </joint>
  <transmission name="rfproximal_transmission" type="pr2_mechanism_model/SimpleTransmission">
    <actuator name="RFJ3"/>
    <joint name="RFJ3"/>
    <mechanicalReduction>1</mechanicalReduction>
    <motorTorqueConstant>1</motorTorqueConstant>
    <pulsesPerRevolution>90000</pulsesPerRevolution>
  </transmission>
  <link name="rfmiddle">
    <inertial>
      <origin rpy="0 0 0" xyz="0 0 0.045"/>
      <mass value="0.012"/>
      <inertia ixx="1.0" ixy="0.0" ixz="0.0" iyy="0.0" iyz="0.0" izz="0.0"/>
    </inertial>
    <visual>
      <origin rpy="0 -1.57079632679 0" xyz="0 0 0"/>
      <geometry name="middle_visual">
        <mesh filename="package://sr_hand/model/meshes/F2.mesh" scale="0.001 0.001 0.001"/>
      </geometry>
      <material name="Grey"/>
    </visual>
    <collision>
      <origin rpy="0 0 0" xyz="0 0 0.0125"/>
      <geometry name="middle_collision_geom">
        <box size="0.005 0.005 0.010"/>
      </geometry>
    </collision>
  </link>
  <gazebo reference="rfmiddle">
    <material>Gazebo/Grey</material>
  </gazebo>
  <joint name="RFJ2" type="revolute">
    <parent link="rfproximal"/>
    <child link="rfmiddle"/>
    <origin rpy="0 0 0" xyz="0 0 0.045"/>
    <axis xyz="1 0 0"/>
    <limit effort="10" lower="0" upper="1.57079632679" velocity="1.0"/>
    <dynamics damping="50.5"/>
  </joint>
  <transmission name="rfmiddle_transmission" type="pr2_mechanism_model/SimpleTransmission">
    <actuator name="RFJ2"/>
    <joint name="RFJ2"/>
    <mechanicalReduction>1</mechanicalReduction>
    <motorTorqueConstant>1</motorTorqueConstant>
    <pulsesPerRevolution>90000</pulsesPerRevolution>
  </transmission>
  <link name="rfdistal">
    <inertial>
      <mass value="0.010"/>
      <origin xyz="0 0 0.025"/>
      <inertia ixx="1.0" ixy="0.0" ixz="0.0" iyy="0.0" iyz="0.0" izz="0.0"/>
    </inertial>
    <visual>
      <origin rpy="0 -1.57079632679 0" xyz="0 0 0"/>
      <geometry name="distal_visual">
        <mesh filename="package://sr_hand/model/meshes/F1.mesh" scale="0.001 0.001 0.001"/>
      </geometry>
      <material name="Grey"/>
    </visual>
    <collision>
      <origin rpy="0 0 0" xyz="0 0 0.02"/>
      <geometry name="distal_collision_geom">
        <box size="0.015 0.015 0.020"/>
      </geometry>
    </collision>
  </link>
  <gazebo reference="rfdistal">
    <material>Gazebo/Grey</material>
  </gazebo>
  <joint name="RFJ1" type="revolute">
    <parent link="rfmiddle"/>
    <child link="rfdistal"/>
    <origin rpy="0 0 0" xyz="0 0 0.025"/>
    <axis xyz="1 0 0"/>
    <limit effort="10" lower="0" upper="1.57079632679" velocity="1.0"/>
    <dynamics damping="50.5"/>
  </joint>
  <transmission name="rfdistal_transmission" type="pr2_mechanism_model/SimpleTransmission">
    <actuator name="RFJ1"/>
    <joint name="RFJ1"/>
    <mechanicalReduction>1</mechanicalReduction>
    <motorTorqueConstant>1</motorTorqueConstant>
    <pulsesPerRevolution>90000</pulsesPerRevolution>
  </transmission>
  <link name="lfmetacarpal">
    <inertial>
      <origin rpy="0 0 0" xyz="0.00568 0 -0.12061"/>
      <mass value="0.075"/>
      <inertia ixx="1.0" ixy="0.0" ixz="0.0" iyy="0.0" iyz="0.0" izz="0.0"/>
    </inertial>
    <visual>
      <origin rpy="0 -1.57079632679 0" xyz="0 0 0"/>
      <geometry name="lfmetacarpal_visual">
        <mesh filename="package://sr_hand/model/meshes/lfmetacarpal.mesh" scale="0.001 0.001 0.001"/>
      </geometry>
      <material name="Grey"/>
    </visual>
    <collision>
      <origin rpy="0 0 0" xyz="-0.015 0 0.015"/>
      <geometry name="lfmetacarpal_collision_geom">
        <box size="0.005 0.005 0.03"/>
      </geometry>
    </collision>
  </link>
  <gazebo reference="lfmetacarpal">
    <material>Gazebo/Grey</material>
  </gazebo>
  <joint name="LFJ5" type="revolute">
    <parent link="palm"/>
    <child link="lfmetacarpal"/>
    <origin rpy="0 0 0" xyz="-0.01671 0 0.044"/>
    <axis xyz="0.57 0 0.82"/>
    <limit effort="10" lower="0" upper="0.69813170079773179" velocity="1.0"/>
    <dynamics damping="50.5"/>
  </joint>
  <transmission name="lfmetacarpal_transmission" type="pr2_mechanism_model/SimpleTransmission">
    <actuator name="LFJ5"/>
    <joint name="LFJ5"/>
    <mechanicalReduction>1</mechanicalReduction>
    <motorTorqueConstant>1</motorTorqueConstant>
    <pulsesPerRevolution>90000</pulsesPerRevolution>
  </transmission>
  <link name="lfknuckle">
    <inertial>
      <origin rpy="0 0 0" xyz="0 0 0.0425"/>
      <mass value="0.008"/>
      <inertia ixx="1.0" ixy="0.0" ixz="0.0" iyy="0.0" iyz="0.0" izz="0.0"/>
    </inertial>
    <visual>
      <origin rpy="3.14159265359 -1.57079632679 -1.57079632679" xyz="0 0 0.0005"/>
      <geometry name="knuckle_visual">
        <mesh filename="package://sr_hand/model/meshes/knuckle.mesh" scale="0.001 0.001 0.001"/>
      </geometry>
      <material name="LightGrey"/>
    </visual>
    <collision>
      <origin rpy="0 0 0" xyz="0 0 0"/>
      <geometry name="knuckle_collision_geom">
        <box size="0.005 0.005 0.005"/>
      </geometry>
    </collision>
  </link>
  <gazebo reference="lfknuckle">
    <material>PR2/Grey2</material>
  </gazebo>
  <joint name="LFJ4" type="revolute">
    <parent link="lfmetacarpal"/>
    <child link="lfknuckle"/>
    <origin rpy="0 0 0" xyz="-0.01671 0 0.044"/>
    <axis xyz="0 1 0"/>
    <limit effort="10" lower="-0.43633231299858238" upper="0.43633231299858238" velocity="1.0"/>
    <dynamics damping="50.5"/>
  </joint>
  <transmission name="lfknuckle_transmission" type="pr2_mechanism_model/SimpleTransmission">
    <actuator name="LFJ4"/>
    <joint name="LFJ4"/>
    <mechanicalReduction>1</mechanicalReduction>
    <motorTorqueConstant>1</motorTorqueConstant>
    <pulsesPerRevolution>90000</pulsesPerRevolution>
  </transmission>
  <link name="lfproximal">
    <inertial>
      <mass value="0.014"/>
      <origin xyz="0 0 0"/>
      <inertia ixx="1.0" ixy="0.0" ixz="0.0" iyy="0.0" iyz="0.0" izz="0.0"/>
    </inertial>
    <visual>
      <origin rpy="0 -1.57079632679 1.57079632679" xyz="0 0 0"/>
      <geometry name="proximal_visual">
        <mesh filename="package://sr_hand/model/meshes/F3.mesh" scale="0.001 0.001 0.001"/>
      </geometry>
      <material name="Grey"/>
    </visual>
    <collision>
      <origin rpy="0 0 0 " xyz="0 0 0.0225"/>
      <geometry name="proximal_collision_geom">
        <box size="0.005 0.005 0.04"/>
      </geometry>
    </collision>
  </link>
  <gazebo reference="lfproximal">
    <material>Gazebo/Grey</material>
  </gazebo>
  <joint name="LFJ3" type="revolute">
    <parent link="lfknuckle"/>
    <child link="lfproximal"/>
    <origin rpy="0 0 0" xyz="0 0 0"/>
    <axis xyz="1 0 0"/>
    <limit effort="10" lower="0" upper="1.57079632679" velocity="1.0"/>
    <dynamics damping="50.5"/>
  </joint>
  <transmission name="lfproximal_transmission" type="pr2_mechanism_model/SimpleTransmission">
    <actuator name="LFJ3"/>
    <joint name="LFJ3"/>
    <mechanicalReduction>1</mechanicalReduction>
    <motorTorqueConstant>1</motorTorqueConstant>
    <pulsesPerRevolution>90000</pulsesPerRevolution>
  </transmission>
  <link name="lfmiddle">
    <inertial>
      <origin rpy="0 0 0" xyz="0 0 0.045"/>
      <mass value="0.012"/>
      <inertia ixx="1.0" ixy="0.0" ixz="0.0" iyy="0.0" iyz="0.0" izz="0.0"/>
    </inertial>
    <visual>
      <origin rpy="0 -1.57079632679 0" xyz="0 0 0"/>
      <geometry name="middle_visual">
        <mesh filename="package://sr_hand/model/meshes/F2.mesh" scale="0.001 0.001 0.001"/>
      </geometry>
      <material name="Grey"/>
    </visual>
    <collision>
      <origin rpy="0 0 0" xyz="0 0 0.0125"/>
      <geometry name="middle_collision_geom">
        <box size="0.005 0.005 0.010"/>
      </geometry>
    </collision>
  </link>
  <gazebo reference="lfmiddle">
    <material>Gazebo/Grey</material>
  </gazebo>
  <joint name="LFJ2" type="revolute">
    <parent link="lfproximal"/>
    <child link="lfmiddle"/>
    <origin rpy="0 0 0" xyz="0 0 0.045"/>
    <axis xyz="1 0 0"/>
    <limit effort="10" lower="0" upper="1.57079632679" velocity="1.0"/>
    <dynamics damping="50.5"/>
  </joint>
  <transmission name="lfmiddle_transmission" type="pr2_mechanism_model/SimpleTransmission">
    <actuator name="LFJ2"/>
    <joint name="LFJ2"/>
    <mechanicalReduction>1</mechanicalReduction>
    <motorTorqueConstant>1</motorTorqueConstant>
    <pulsesPerRevolution>90000</pulsesPerRevolution>
  </transmission>
  <link name="lfdistal">
    <inertial>
      <mass value="0.010"/>
      <origin xyz="0 0 0.025"/>
      <inertia ixx="1.0" ixy="0.0" ixz="0.0" iyy="0.0" iyz="0.0" izz="0.0"/>
    </inertial>
    <visual>
      <origin rpy="0 -1.57079632679 0" xyz="0 0 0"/>
      <geometry name="distal_visual">
        <mesh filename="package://sr_hand/model/meshes/F1.mesh" scale="0.001 0.001 0.001"/>
      </geometry>
      <material name="Grey"/>
    </visual>
    <collision>
      <origin rpy="0 0 0" xyz="0 0 0.02"/>
      <geometry name="distal_collision_geom">
        <box size="0.015 0.015 0.020"/>
      </geometry>
    </collision>
  </link>
  <gazebo reference="lfdistal">
    <material>Gazebo/Grey</material>
  </gazebo>
  <joint name="LFJ1" type="revolute">
    <parent link="lfmiddle"/>
    <child link="lfdistal"/>
    <origin rpy="0 0 0" xyz="0 0 0.025"/>
    <axis xyz="1 0 0"/>
    <limit effort="10" lower="0" upper="1.57079632679" velocity="1.0"/>
    <dynamics damping="50.5"/>
  </joint>
  <transmission name="lfdistal_transmission" type="pr2_mechanism_model/SimpleTransmission">
    <actuator name="LFJ1"/>
    <joint name="LFJ1"/>
    <mechanicalReduction>1</mechanicalReduction>
    <motorTorqueConstant>1</motorTorqueConstant>
    <pulsesPerRevolution>90000</pulsesPerRevolution>
  </transmission>
  <link name="thbase">
    <inertial>
      <mass value="0.010"/>
      <origin rpy="0 0 0" xyz="0.034 0.0085 0.02924"/>
      <inertia ixx="1.0" ixy="0.0" ixz="0.0" iyy="0.0" iyz="0.0" izz="0.0"/>
    </inertial>
    <visual>
      <origin rpy="0 0 0" xyz="0 0 0"/>
      <geometry name="thbase_visual">
        <box size="0.001 0.001 0.001"/>
      </geometry>
      <material name="shadow_thbase_material">
        <color rgba="0.5 0.5 0.5 1.0"/>
      </material>
    </visual>
    <collision>
      <origin rpy="0 0 0 " xyz="0 0 0"/>
      <geometry name="thbase_collision_geom">
        <box size="0.001 0.001 0.001"/>
      </geometry>
    </collision>
  </link>
  <gazebo reference="thbase">
    <material>Gazebo/Grey</material>
  </gazebo>
  <joint name="THJ5" type="revolute">
    <parent link="palm"/>
    <child link="thbase"/>
    <origin rpy="0 0.785398163397 0" xyz="0.034 -0.0085 0.02924"/>
    <axis xyz="0 0 -1"/>
    <limit effort="10" lower="-1.047" upper="1.047" velocity="1.0"/>
    <dynamics damping="50.5"/>
  </joint>
  <transmission name="thbase_transmission" type="pr2_mechanism_model/SimpleTransmission">
    <actuator name="THJ5"/>
    <joint name="THJ5"/>
    <mechanicalReduction>1</mechanicalReduction>
    <motorTorqueConstant>1</motorTorqueConstant>
    <pulsesPerRevolution>90000</pulsesPerRevolution>
  </transmission>
  <link name="thproximal">
    <inertial>
      <mass value="0.016"/>
      <origin rpy="0 0 0" xyz="0 0 0"/>
      <inertia ixx="1.0" ixy="0.0" ixz="0.0" iyy="0.0" iyz="0.0" izz="0.0"/>
    </inertial>
    <visual>
      <origin rpy="0 0 0" xyz="0 0 0"/>
      <geometry name="thproximal_visual">
        <mesh filename="package://sr_hand/model/meshes/TH3_z.mesh" scale="0.01 0.01 0.01"/>
      </geometry>
      <material name="shadow_thproximal_material">
        <color rgba="0.2 0.2 0.2 1.0"/>
      </material>
    </visual>
    <collision>
      <origin rpy="0 0 0" xyz="0 0 0.02"/>
      <geometry name="thproximal_collision_geom">
        <box size="0.005 0.005 0.02"/>
      </geometry>
    </collision>
  </link>
  <gazebo reference="thproximal">
    <material>Gazebo/Grey</material>
  </gazebo>
  <joint name="THJ4" type="revolute">
    <parent link="thbase"/>
    <child link="thproximal"/>
    <origin rpy="0 0 0" xyz="0 0 0"/>
    <axis xyz="1 0 0"/>
    <limit effort="10" lower="0" upper="1.309" velocity="1.0"/>
    <dynamics damping="50.5"/>
  </joint>
  <transmission name="thproximal_transmission" type="pr2_mechanism_model/SimpleTransmission">
    <actuator name="THJ4"/>
    <joint name="THJ4"/>
    <mechanicalReduction>1</mechanicalReduction>
    <motorTorqueConstant>1</motorTorqueConstant>
    <pulsesPerRevolution>90000</pulsesPerRevolution>
  </transmission>
  <link name="thhub">
    <inertial>
      <mass value="0.002"/>
      <origin rpy="0 0 0" xyz="0.02687 0 0.02687"/>
      <inertia ixx="1.0" ixy="0.0" ixz="0.0" iyy="0.0" iyz="0.0" izz="0.0"/>
    </inertial>
    <visual>
      <origin rpy="0 0 0" xyz="0 0 0"/>
      <geometry name="thhub_visual">
        <box size="0.001 0.001 0.001"/>
      </geometry>
      <material name="shadow_thhub_material">
        <color rgba="0.7 0.7 0.7 1.0"/>
      </material>
    </visual>
    <collision>
      <origin rpy="0 0 0 " xyz="0 0 0"/>
      <geometry name="thhub_collision_geom">
        <box size="0.001 0.001 0.001"/>
      </geometry>
    </collision>
  </link>
  <gazebo reference="thhub">
    <material>Gazebo/Grey</material>
  </gazebo>
  <joint name="THJ3" type="revolute">
    <parent link="thproximal"/>
    <child link="thhub"/>
    <origin rpy="0 0 0" xyz="0 0 0.038"/>
    <axis xyz="1 0 0"/>
    <limit effort="10" lower="-0.2618" upper="0.2618" velocity="1.0"/>
    <dynamics damping="50.5"/>
  </joint>
  <transmission name="thhub_transmission" type="pr2_mechanism_model/SimpleTransmission">
    <actuator name="THJ3"/>
    <joint name="THJ3"/>
    <mechanicalReduction>1</mechanicalReduction>
    <motorTorqueConstant>1</motorTorqueConstant>
    <pulsesPerRevolution>90000</pulsesPerRevolution>
  </transmission>
  <link name="thmiddle">
    <inertial>
      <mass value="0.016"/>
      <origin rpy="0 0 0" xyz="0 0 0"/>
      <inertia ixx="1.0" ixy="0.0" ixz="0.0" iyy="0.0" iyz="0.0" izz="0.0"/>
    </inertial>
    <visual>
      <origin rpy="0 -1.57079632679 0" xyz="0 0 0"/>
      <geometry name="thmiddle_visual">
        <mesh filename="package://sr_hand/model/meshes/TH2_z.mesh" scale="0.001 0.001 0.001"/>
      </geometry>
      <material name="shadow_thmiddle_material">
        <color rgba="0.2 0.2 0.2 1.0"/>
      </material>
    </visual>
    <collision>
      <origin rpy="0 0 0 " xyz="0 0 0.025"/>
      <geometry name="thmiddle_collision_geom">
        <box size="0.005 0.005 0.015"/>
      </geometry>
    </collision>
  </link>
  <gazebo reference="thmiddle">
    <material>Gazebo/Grey</material>
  </gazebo>
  <joint name="THJ2" type="revolute">
    <parent link="thhub"/>
    <child link="thmiddle"/>
    <origin rpy="0 0 0" xyz="0 0 0"/>
    <axis xyz="0 -1 0"/>
    <limit effort="10" lower="-0.5237" upper="0.5237" velocity="1.0"/>
    <dynamics damping="50.5"/>
  </joint>
  <transmission name="thmiddle_transmission" type="pr2_mechanism_model/SimpleTransmission">
    <actuator name="THJ2"/>
    <joint name="THJ2"/>
    <mechanicalReduction>1</mechanicalReduction>
    <motorTorqueConstant>1</motorTorqueConstant>
    <pulsesPerRevolution>90000</pulsesPerRevolution>
  </transmission>
  <link name="thdistal">
    <inertial>
      <mass value="0.016"/>
      <origin rpy="0 0 0" xyz="-0.02263 0 0.02263"/>
      <inertia ixx="1.0" ixy="0.0" ixz="0.0" iyy="0.0" iyz="0.0" izz="0.0"/>
    </inertial>
    <visual>
      <origin rpy="3.14159265359 -1.57079632679 3.14159265359" xyz="0 0 0"/>
      <geometry name="thdistal_visual">
        <mesh filename="package://sr_hand/model/meshes/TH1_z.mesh" scale="0.001 0.001 0.001"/>
      </geometry>
      <material name="shadow_thmiddle_material">
        <color rgba="0.2 0.2 0.2 1.0"/>
      </material>
    </visual>
    <collision>
      <origin rpy="0 0 0 " xyz="0 0 0.025"/>
      <geometry name="thmiddle_collision_geom">
        <box size="0.015 0.015 0.015"/>
      </geometry>
    </collision>
  </link>
  <gazebo reference="thdistal">
    <material>Gazebo/Grey</material>
  </gazebo>
  <joint name="THJ1" type="revolute">
    <parent link="thmiddle"/>
    <child link="thdistal"/>
    <origin rpy="0 0 0" xyz="0 0 0.032"/>
    <axis xyz="0 -1 0"/>
    <limit effort="10" lower="0" upper="1.571" velocity="1.0"/>
    <dynamics damping="50.5"/>
  </joint>
  <transmission name="thdistal_transmission" type="pr2_mechanism_model/SimpleTransmission">
    <actuator name="THJ1"/>
    <joint name="THJ1"/>
    <mechanicalReduction>1</mechanicalReduction>
    <motorTorqueConstant>1</motorTorqueConstant>
    <pulsesPerRevolution>90000</pulsesPerRevolution>
  </transmission>
  <!-- Joining them togheter -->
  <joint name="PAM_Hand_Joint" type="fixed">
    <origin rpy="0 0 0" xyz="0 0  0.0175"/>
    <parent link="PAM100"/>
    <child link="forearm_motor"/>
  </joint>
</robot>

